<mujoco model="sharpa_left">
  <compiler angle="radian" meshdir="meshes/" autolimits="true" />
  <default>
    <!-- disable all contacts and use explicit collision pairs -->
    <geom density="800" condim="1" contype="0" conaffinity="0" />
    <!-- with this setting, the response time is around 1s -->
    <position kp="300" dampratio="1.0" inheritrange="1" />
    <joint damping="0.0" armature="1.0" frictionloss="0.0" />
    <site size="0.005" type="sphere" rgba="1 0 0 1" group="3" />
  </default>
  <asset>
    <texture type="skybox" builtin="gradient" rgb1="1.0 1.0 1.0" rgb2="1.0 1.0 1.0" width="512" height="3072" />
    <texture type="2d" name="left_groundplane" builtin="checker" mark="edge" rgb1="0.2 0.3 0.4" rgb2="0.1 0.2 0.3" markrgb="0.8 0.8 0.8" width="300" height="300" />
    <material name="left_groundplane" texture="left_groundplane" texuniform="true" texrepeat="5 5" reflectance="0.2" />
    <mesh name="left_hand_C_MC_visual" file="left_hand_C_MC_visual_.STL" />
    <mesh name="left_hand_C_MC" file="left_hand_C_MC.STL" />
    <mesh name="left_thumb_CMC_VL_visual" file="left_thumb_CMC_VL.STL" />
    <mesh name="left_thumb_MC_visual" file="left_thumb_MC_visual.STL" />
    <mesh name="left_thumb_MC" file="left_thumb_MC.STL" />
    <mesh name="left_thumb_MCP_VL_visual" file="left_thumb_MCP_VL_visual.STL" />
    <mesh name="left_thumb_PP_visual" file="left_thumb_PP_visual.STL" />
    <mesh name="left_thumb_PP" file="left_thumb_PP.STL" />
    <mesh name="left_thumb_DP_visual" file="left_thumb_DP_visual.STL" />
    <mesh name="left_thumb_DP" file="left_thumb_DP.STL" />
    <mesh name="left_thumb_elastomer_surface" file="thumb_elastomer_surface.STL" />
    <mesh name="left_thumb_elastomer" file="thumb_elastomer.STL" />
    <mesh name="left_MCP_VL_visual" file="left_MCP_VL_visual.STL" />
    <mesh name="left_MCP_VL" file="left_MCP_VL.STL" />
    <mesh name="left_PP_visual" file="left_PP_visual.STL" />
    <mesh name="left_PP" file="left_PP.STL" />
    <mesh name="left_MP_visual" file="left_MP_visual.STL" />
    <mesh name="left_MP" file="left_MP.STL" />
    <mesh name="left_DP_visual" file="left_DP_visual.STL" />
    <mesh name="left_DP" file="left_DP.STL" />
    <mesh name="left_elastomer_surface" file="elastomer_surface.STL" />
    <mesh name="left_elastomer" file="elastomer.STL" />
    <mesh name="left_pinky_MC_visual" file="left_pinky_MC_visual.STL" />
    <mesh name="left_pinky_MC" file="left_pinky_MC.STL" />
  </asset>
  <worldbody>
    <body name="left_base_tx">
      <inertial pos="0 0 0" mass="0.1" diaginertia="0.01 0.01 0.01" />
      <joint name="left_pos_x" pos="0 0 0" axis="1 0 0" type="slide" range="-5 5" />
      <body name="left_base_ty">
        <inertial pos="0 0 0" mass="0.1" diaginertia="0.01 0.01 0.01" />
        <joint name="left_pos_y" pos="0 0 0" axis="0 1 0" type="slide" range="-5 5" />
        <body name="left_base_tz">
          <inertial pos="0 0 0" mass="0.1" diaginertia="0.01 0.01 0.01" />
          <joint name="left_pos_z" pos="0 0 0" axis="0 0 1" type="slide" range="-5 5" />
          <body name="left_base_roll">
            <inertial pos="0 0 0" mass="0.1" diaginertia="0.01 0.01 0.01" />
            <joint name="left_rot_x" pos="0 0 0" axis="1 0 0" type="hinge" range="-6.28 6.28" />
            <body name="left_base_pitch">
              <inertial pos="0 0 0" mass="0.1" diaginertia="0.01 0.01 0.01" />
              <joint name="left_rot_y" pos="0 0 0" axis="0 1 0" type="hinge" range="-6.28 6.28" />
              <body name="left_base_yaw">
                <inertial pos="0 0 0" mass="0.1" diaginertia="0.01 0.01 0.01" />
                <joint name="left_rot_z" pos="0 0 0" axis="0 0 1" type="hinge" range="-6.28 6.28" />
                <body name="left_hand_C_MC" pos="0 0 0">
                  <inertial pos="0.0060282 0.00091891 0.038914" mass="0.72045" diaginertia="0.00071328 0.00081371 0.00020795" />
                  <geom type="mesh" contype="0" conaffinity="0" group="1" density="0" rgba="0.79216 0.81961 0.93333 1" mesh="left_hand_C_MC_visual" name="left_hand_C_MC_visual" />
                  <body name="left_thumb_CMC_VL" pos="0.01 -0.026 0.0212" quat="0.707105 0 0 -0.707108">
                    <site name="left_thumb_mcp" pos="0 0 0" />
                    <inertial pos="0 0 0" mass="1e-06" diaginertia="2e-12 2e-12 2e-12" />
                    <joint name="left_thumb_CMC_FE" pos="0 0 0" axis="0 0 1" range="-0.1745 1.9199" />
                    <geom type="mesh" contype="0" conaffinity="0" group="1" density="0" rgba="0.79216 0.81961 0.93333 1" mesh="left_thumb_CMC_VL_visual" />
                    <body name="left_thumb_MC" pos="0 -0.005 0" quat="0.65328 0.653282 -0.270598 0.270599">
                      <inertial pos="0.0385056 -0.0105846 -0.00991873" quat="0.158428 0.667584 0.222963 0.692474" mass="0.116" diaginertia="3.83518e-05 3.34032e-05 1.641e-05" />
                      <joint name="left_thumb_CMC_AA" pos="0 0 0" axis="0 0 1" range="-0.3491 0.3491" />
                      <geom type="mesh" contype="0" conaffinity="0" group="1" density="0" rgba="0.79216 0.81961 0.93333 1" mesh="left_thumb_MC_visual" name="left_thumb_MC_visual" />
                      <body name="left_thumb_MCP_VL" pos="0.065 -0.006 -0.010392" quat="0.965926 -0.25882 0 0">
                        <site name="left_thumb_pip" pos="0 0 0" />
                        <inertial pos="4.8e-09 0.000869809 -3.6e-09" mass="0.001" diaginertia="2e-12 2e-12 2e-12" />
                        <joint name="left_thumb_MCP_FE" pos="0 0 0" axis="0 0 1" range="-0.5236 1.3963" />
                        <geom type="mesh" contype="0" conaffinity="0" group="1" density="0" rgba="0.79216 0.81961 0.93333 1" mesh="left_thumb_MCP_VL_visual" />
                        <body name="left_thumb_PP" quat="0.707105 0.707108 0 0">
                          <inertial pos="0.0219483 -0.00015581 0.00149446" quat="0.526585 0.473016 0.473458 0.524215" mass="0.04955" diaginertia="4.60001e-06 4.35675e-06 2.57733e-06" />
                          <joint name="left_thumb_MCP_AA" pos="0 0 0" axis="0 0 1" range="-0.3491 0.3491" />
                          <geom type="mesh" contype="0" conaffinity="0" group="1" density="0" rgba="0.79216 0.81961 0.93333 1" mesh="left_thumb_PP_visual" name="left_thumb_PP_visual" />
                          <body name="left_thumb_DP" pos="0.039 0 0" quat="0.707105 -0.707108 0 0">
                            <site name="left_thumb_dip" pos="0 0 0" />
                            <inertial pos="0.00985829 -0.0101254 0.00044771" quat="0.649916 0.20258 -0.647399 0.342703" mass="0.006986" diaginertia="8.79989e-07 8.08573e-07 2.50588e-07" />
                            <joint name="left_thumb_IP" pos="0 0 0" axis="0 0 1" range="0 1.7453" />
                            <geom type="mesh" contype="0" conaffinity="0" group="1" density="0" rgba="0.79216 0.81961 0.93333 1" mesh="left_thumb_DP_visual" name="left_thumb_DP_visual" />
                            <geom quat="0.5 0.5 -0.5 0.5" type="mesh" contype="0" conaffinity="0" group="1" density="0" rgba="0.2 1 0.2 1" mesh="left_thumb_elastomer" />
                            <geom name="collision_hand_left_thumb_0" type="capsule" size="0.007" fromto="0.022 -0.003 0 0 0.002 0" group="3" rgba="0 1 0 1" />
                            <site name="left_thumb_tip" pos="0.015 0 0" />
                            <site name="track_hand_left_thumb_tip" pos="0.015 0 0" />
                            <site name="trace_hand_left_thumb_tip" pos="0.015 0 0" />
                          </body>
                          <geom name="collision_hand_left_thumb_1" type="capsule" size="0.012" fromto="0.039 0 0 0 0 0" group="3" rgba="0 1 0 1" />
                        </body>
                      </body>
                      <geom name="collision_hand_left_thumb_2" type="capsule" size="0.015" fromto="0.065 -0.006 -0.01 0 0 0" group="3" rgba="0 1 0 1" />
                    </body>
                  </body>
                  <body name="left_index_MCP_VL" pos="0.001 -0.0303 0.0957" quat="0.499998 -0.500002 -0.5 -0.5">
                    <site name="left_index_mcp" pos="0 0 0" />
                    <inertial pos="4.8e-09 0.00086981 -3.6e-09" mass="0.001" diaginertia="2e-12 2e-12 2e-12" />
                    <joint name="left_index_MCP_FE" pos="0 0 0" axis="0 0 1" range="-0.17453293 1.5708" />
                    <geom type="mesh" contype="0" conaffinity="0" group="1" density="0" rgba="0.79216 0.81961 0.93333 1" mesh="left_MCP_VL_visual" name="left_index_MCP_VL_visual" />
                    <body name="left_index_PP" quat="0.707105 0.707108 0 0">
                      <inertial pos="0.0243772 -1.00263e-06 0.000755901" quat="0.519877 0.479286 0.479204 0.519977" mass="0.04138" diaginertia="6.82371e-06 6.54097e-06 2.16753e-06" />
                      <joint name="left_index_MCP_AA" pos="0 0 0" axis="0 0 1" range="-0.3491 0.3491" />
                      <geom type="mesh" contype="0" conaffinity="0" group="1" density="0" rgba="0.79216 0.81961 0.93333 1" mesh="left_PP_visual" name="left_index_PP_visual" />
                      <body name="left_index_MP" pos="0.047 0 0" quat="0.707105 -0.707108 0 0">
                        <site name="left_index_pip" pos="0 0 0" />
                        <inertial pos="0.015316 -0.00138561 6.27987e-08" quat="-0.0196259 0.706839 0.0195186 0.706832" mass="0.02509" diaginertia="2.28516e-06 2.26758e-06 9.99868e-07" />
                        <joint name="left_index_PIP" pos="0 0 0" axis="0 0 1" range="0 1.7453" />
                        <geom type="mesh" contype="0" conaffinity="0" group="1" density="0" rgba="0.79216 0.81961 0.93333 1" mesh="left_MP_visual" name="left_index_MP_visual" />
                        <body name="left_index_DP" pos="0.0315 0 0">
                          <site name="left_index_dip" pos="0 0 0" />
                          <inertial pos="0.00931302 -0.00769378 0.000111984" quat="0.643869 0.245527 -0.649442 0.321517" mass="0.005102" diaginertia="4.23794e-07 3.8546e-07 1.37255e-07" />
                          <joint name="left_index_DIP" pos="0 0 0" axis="0 0 1" range="0 1.3963" />
                          <geom type="mesh" contype="0" conaffinity="0" group="1" density="0" rgba="0.79216 0.81961 0.93333 1" mesh="left_DP_visual" name="left_index_DP_visual" />
                          <geom quat="0.5 0.5 -0.5 0.5" type="mesh" contype="0" conaffinity="0" group="1" density="0" rgba="0.2 1 0.2 1" mesh="left_elastomer" name="left_index_elastomer_visual" />
                          <geom name="collision_hand_left_index_0" type="capsule" size="0.007" fromto="0.02 -0.002 0 0 0 0" group="3" rgba="0 1 0 1" />
                          <site name="left_index_tip" pos="0.014 0 0" />
                          <site name="track_hand_left_index_tip" pos="0.014 0 0" />
                          <site name="trace_hand_left_index_tip" pos="0.014 0 0" />
                        </body>
                        <geom name="collision_hand_left_index_1" type="capsule" size="0.009" fromto="0.0315 0 0 0 0 0" group="3" rgba="0 1 0 1" />
                      </body>
                      <geom name="collision_hand_left_index_2" type="capsule" size="0.01" fromto="0.047 0 0 0 0 0" group="3" rgba="0 1 0 1" />
                    </body>
                  </body>
                  <body name="left_middle_MCP_VL" pos="0 -0.01 0.0987" quat="0.499998 -0.500002 -0.5 -0.5">
                    <site name="left_middle_mcp" pos="0 0 0" />
                    <inertial pos="4.8e-09 0.00086981 -3.6e-09" mass="1e-06" diaginertia="2e-12 2e-12 2e-12" />
                    <joint name="left_middle_MCP_FE" pos="0 0 0" axis="0 0 1" range="-0.17453293 1.5708" />
                    <geom type="mesh" contype="0" conaffinity="0" group="1" density="0" rgba="0.79216 0.81961 0.93333 1" mesh="left_MCP_VL_visual" name="left_middle_MCP_VL_visual" />
                    <body name="left_middle_PP" quat="0.707105 0.707108 0 0">
                      <inertial pos="0.0243772 -1.00263e-06 0.000755901" quat="0.519877 0.479286 0.479204 0.519977" mass="0.04138" diaginertia="6.82371e-06 6.54097e-06 2.16753e-06" />
                      <joint name="left_middle_MCP_AA" pos="0 0 0" axis="0 0 1" range="-0.3491 0.3491" />
                      <geom type="mesh" contype="0" conaffinity="0" group="1" density="0" rgba="0.79216 0.81961 0.93333 1" mesh="left_PP_visual" name="left_middle_PP_visual" />
                      <body name="left_middle_MP" pos="0.047 0 0" quat="0.707105 -0.707108 0 0">
                        <site name="left_middle_pip" pos="0 0 0" />
                        <inertial pos="0.015316 -0.00138561 6.27987e-08" quat="-0.0196259 0.706839 0.0195186 0.706832" mass="0.02509" diaginertia="2.28516e-06 2.26758e-06 9.99868e-07" />
                        <joint name="left_middle_PIP" pos="0 0 0" axis="0 0 1" range="0 1.7453" />
                        <geom type="mesh" contype="0" conaffinity="0" group="1" density="0" rgba="0.79216 0.81961 0.93333 1" mesh="left_MP_visual" name="left_middle_MP_visual" />
                        <body name="left_middle_DP" pos="0.0315 0 0">
                          <site name="left_middle_dip" pos="0 0 0" />
                          <inertial pos="0.00931302 -0.00769378 0.000111984" quat="0.643869 0.245527 -0.649442 0.321517" mass="0.005102" diaginertia="4.23794e-07 3.8546e-07 1.37255e-07" />
                          <joint name="left_middle_DIP" pos="0 0 0" axis="0 0 1" range="0 1.3963" />
                          <geom type="mesh" contype="0" conaffinity="0" group="1" density="0" rgba="0.79216 0.81961 0.93333 1" mesh="left_DP_visual" name="left_middle_DP_visual" />
                          <geom quat="0.5 0.5 -0.5 0.5" type="mesh" contype="0" conaffinity="0" group="1" density="0" rgba="0.2 1 0.2 1" mesh="left_elastomer" name="left_middle_elastomer_visual" />
                          <geom name="collision_hand_left_middle_0" type="capsule" size="0.007" fromto="0.02 -0.002 0 0 0 0" group="3" rgba="0 1 0 1" />
                          <site name="left_middle_tip" pos="0.014 0 0" />
                          <site name="track_hand_left_middle_tip" pos="0.014 0 0" />
                          <site name="trace_hand_left_middle_tip" pos="0.014 0 0" />
                        </body>
                        <geom name="collision_hand_left_middle_1" type="capsule" size="0.009" fromto="0.0315 0 0 0 0 0" group="3" rgba="0 1 0 1" />
                      </body>
                      <geom name="collision_hand_left_middle_2" type="capsule" size="0.01" fromto="0.047 0 0 0 0 0" group="3" rgba="0 1 0 1" />
                    </body>
                  </body>
                  <body name="left_ring_MCP_VL" pos="0.0015 0.0103 0.0927" quat="0.499998 -0.500002 -0.5 -0.5">
                    <site name="left_ring_mcp" pos="0 0 0" />
                    <inertial pos="4.8e-09 0.00086981 3.6e-09" mass="1e-06" diaginertia="2e-12 2e-12 2e-12" />
                    <joint name="left_ring_MCP_FE" pos="0 0 0" axis="0 0 1" range="-0.17453293 1.5708" />
                    <geom type="mesh" contype="0" conaffinity="0" group="1" density="0" rgba="0.79216 0.81961 0.93333 1" mesh="left_MCP_VL_visual" name="left_ring_MCP_VL_visual" />
                    <body name="left_ring_PP" quat="0.707105 0.707108 0 0">
                      <inertial pos="0.0243772 -1.00263e-06 0.000755901" quat="0.519877 0.479286 0.479204 0.519977" mass="0.04138" diaginertia="6.82371e-06 6.54097e-06 2.16753e-06" />
                      <joint name="left_ring_MCP_AA" pos="0 0 0" axis="0 0 1" range="-0.3491 0.3491" />
                      <geom type="mesh" contype="0" conaffinity="0" group="1" density="0" rgba="0.79216 0.81961 0.93333 1" mesh="left_PP_visual" name="left_ring_PP_visual" />
                      <body name="left_ring_MP" pos="0.047 0 0" quat="0.707105 -0.707108 0 0">
                        <site name="left_ring_pip" pos="0 0 0" />
                        <inertial pos="0.015316 -0.00138561 6.27987e-08" quat="-0.0196259 0.706839 0.0195186 0.706832" mass="0.02509" diaginertia="2.28516e-06 2.26758e-06 9.99868e-07" />
                        <joint name="left_ring_PIP" pos="0 0 0" axis="0 0 1" range="0 1.7453" />
                        <geom type="mesh" contype="0" conaffinity="0" group="1" density="0" rgba="0.79216 0.81961 0.93333 1" mesh="left_MP_visual" name="left_ring_MP_visual" />
                        <body name="left_ring_DP" pos="0.0315 0 0">
                          <site name="left_ring_dip" pos="0 0 0" />
                          <inertial pos="0.00931208 -0.00769378 0.000111984" quat="0.643953 0.245771 -0.649317 0.321417" mass="0.005102" diaginertia="4.23686e-07 3.85387e-07 1.37226e-07" />
                          <joint name="left_ring_DIP" pos="0 0 0" axis="0 0 1" range="0 1.3963" />
                          <geom type="mesh" contype="0" conaffinity="0" group="1" density="0" rgba="0.79216 0.81961 0.93333 1" mesh="left_DP_visual" name="left_ring_DP_visual" />
                          <geom quat="0.499998 0.5 -0.5 0.500002" type="mesh" contype="0" conaffinity="0" group="1" density="0" rgba="0.2 1 0.2 1" mesh="left_elastomer" name="left_ring_elastomer_visual" />
                          <geom name="collision_hand_left_ring_0" type="capsule" size="0.007" fromto="0.02 -0.002 0 0 0 0" group="3" rgba="0 1 0 1" />
                          <site name="left_ring_tip" pos="0.014 0 0" />
                          <site name="track_hand_left_ring_tip" pos="0.014 0 0" />
                          <site name="trace_hand_left_ring_tip" pos="0.014 0 0" />
                        </body>
                        <geom name="collision_hand_left_ring_1" type="capsule" size="0.009" fromto="0.0315 0 0 0 0 0" group="3" rgba="0 1 0 1" />
                      </body>
                      <geom name="collision_hand_left_ring_2" type="capsule" size="0.01" fromto="0.047 0 0 0 0 0" group="3" rgba="0 1 0 1" />
                    </body>
                  </body>
                  <body name="left_pinky_MC" pos="0.01136 0.0263 0.0867" quat="1.34924e-11 3.67321e-06 -1 -3.67321e-06">
                    <inertial pos="0.0107985 0.00598801 0.0335125" quat="0.709657 0.106152 0.0812795 0.691746" mass="0.12541" diaginertia="3.57685e-05 2.46485e-05 2.14424e-05" />
                    <joint name="left_pinky_CMC" pos="0 0 0" axis="0 0 1" range="0 0.2618" />
                    <geom type="mesh" contype="0" conaffinity="0" group="1" density="0" rgba="0.79216 0.81961 0.93333 1" mesh="left_pinky_MC_visual" name="left_pinky_MC_visual" />
                    <body name="left_pinky_MCP_VL" pos="0.00836 0.0048 0" quat="0.499998 -0.5 0.5 0.500002">
                      <site name="left_pinky_mcp" pos="0 0 0" />
                      <inertial pos="4.8e-09 0.00086981 -3.6e-09" mass="0.001" diaginertia="2e-12 2e-12 2e-12" />
                      <joint name="left_pinky_MCP_FE" pos="0 0 0" axis="0 0 1" range="-0.17453293 1.5708" />
                      <geom type="mesh" contype="0" conaffinity="0" group="1" density="0" rgba="0.79216 0.81961 0.93333 1" mesh="left_MCP_VL_visual" name="left_pinky_MCP_VL_visual" />
                      <body name="left_pinky_PP" quat="0.707105 0.707108 0 0">
                        <inertial pos="0.0243772 -1.00263e-06 0.000755901" quat="0.519877 0.479286 0.479204 0.519977" mass="0.04138" diaginertia="6.82371e-06 6.54097e-06 2.16753e-06" />
                        <joint name="left_pinky_MCP_AA" pos="0 0 0" axis="0 0 1" range="-0.3491 0.3491" />
                        <geom type="mesh" contype="0" conaffinity="0" group="1" density="0" rgba="0.79216 0.81961 0.93333 1" mesh="left_PP_visual" name="left_pinky_PP_visual" />
                        <body name="left_pinky_MP" pos="0.047 0 0" quat="0.707105 -0.707108 0 0">
                          <site name="left_pinky_pip" pos="0 0 0" />
                          <inertial pos="0.015316 -0.00138561 6.27987e-08" quat="-0.0196259 0.706839 0.0195186 0.706832" mass="0.02509" diaginertia="2.28516e-06 2.26758e-06 9.99868e-07" />
                          <joint name="left_pinky_PIP" pos="0 0 0" axis="0 0 1" range="0 1.7453" />
                          <geom type="mesh" contype="0" conaffinity="0" group="1" density="0" rgba="0.79216 0.81961 0.93333 1" mesh="left_MP_visual" name="left_pinky_MP_visual" />
                          <body name="left_pinky_DP" pos="0.0315 0 0">
                            <site name="left_pinky_dip" pos="0 0 0" />
                            <inertial pos="0.00931208 -0.00769378 0.000111984" quat="0.643953 0.245771 -0.649317 0.321417" mass="0.005102" diaginertia="4.23686e-07 3.85387e-07 1.37226e-07" />
                            <joint name="left_pinky_DIP" pos="0 0 0" axis="0 0 1" range="0 1.3963" />
                            <geom type="mesh" contype="0" conaffinity="0" group="1" density="0" rgba="0.79216 0.81961 0.93333 1" mesh="left_DP_visual" name="left_pinky_DP_visual" />
                            <geom quat="0.5 0.5 -0.5 0.5" type="mesh" contype="0" conaffinity="0" group="1" density="0" rgba="0.2 1 0.2 1" mesh="left_elastomer" name="left_pinky_elastomer_visual" />
                            <geom name="collision_hand_left_pinky_0" type="capsule" size="0.007" fromto="0.02 -0.002 0 0 0 0" group="3" rgba="0 1 0 1" />
                            <site name="left_pinky_tip" pos="0.014 0 0" />
                            <site name="track_hand_left_pinky_tip" pos="0.014 0 0" />
                            <site name="trace_hand_left_pinky_tip" pos="0.014 0 0" />
                          </body>
                          <geom name="collision_hand_left_pinky_1" type="capsule" size="0.008" fromto="0.0315 0 0 0 0 0" group="3" rgba="0 1 0 1" />
                        </body>
                        <geom name="collision_hand_left_pinky_2" type="capsule" size="0.009" fromto="0.047 0 0 0 0 0" group="3" rgba="0 1 0 1" />
                      </body>
                    </body>
                  </body>
                  <geom name="collision_hand_left_palm_0" type="box" size="0.016 0.035 0.035" pos="-0 0 0.05" quat="0 0 1 0" group="3" rgba="0 1 0 1" />
                  <site name="left_palm" pos="0 0 0.05" type="box" size="0.01 0.02 0.03" />
                </body>
              </body>
            </body>
          </body>
        </body>
      </body>
      <camera name="left_track" pos="0.868 -0.348 -0.175" xyaxes="0.037 0.999 -0.000 0.011 -0.000 1.000" />
    </body>
  </worldbody>
  <actuator>
    <position name="left_pos_x_position" joint="left_pos_x" kp="1000" />
    <position name="left_pos_y_position" joint="left_pos_y" kp="1000" />
    <position name="left_pos_z_position" joint="left_pos_z" kp="1000" />
    <position name="left_rot_x_position" joint="left_rot_x" kp="1000" />
    <position name="left_rot_y_position" joint="left_rot_y" kp="1000" />
    <position name="left_rot_z_position" joint="left_rot_z" kp="1000" />
    <position name="left_thumb_CMC_FE_position" joint="left_thumb_CMC_FE" />
    <position name="left_thumb_CMC_AA_position" joint="left_thumb_CMC_AA" />
    <position name="left_thumb_MCP_FE_position" joint="left_thumb_MCP_FE" />
    <position name="left_thumb_MCP_AA_position" joint="left_thumb_MCP_AA" />
    <position name="left_thumb_IP_position" joint="left_thumb_IP" />
    <position name="left_index_MCP_FE_position" joint="left_index_MCP_FE" />
    <position name="left_index_MCP_AA_position" joint="left_index_MCP_AA" />
    <position name="left_index_PIP_position" joint="left_index_PIP" />
    <position name="left_index_DIP_position" joint="left_index_DIP" />
    <position name="left_middle_MCP_FE_position" joint="left_middle_MCP_FE" />
    <position name="left_middle_MCP_AA_position" joint="left_middle_MCP_AA" />
    <position name="left_middle_PIP_position" joint="left_middle_PIP" />
    <position name="left_middle_DIP_position" joint="left_middle_DIP" />
    <position name="left_ring_MCP_FE_position" joint="left_ring_MCP_FE" />
    <position name="left_ring_MCP_AA_position" joint="left_ring_MCP_AA" />
    <position name="left_ring_PIP_position" joint="left_ring_PIP" />
    <position name="left_ring_DIP_position" joint="left_ring_DIP" />
    <position name="left_pinky_CMC_position" joint="left_pinky_CMC" />
    <position name="left_pinky_MCP_FE_position" joint="left_pinky_MCP_FE" />
    <position name="left_pinky_MCP_AA_position" joint="left_pinky_MCP_AA" />
    <position name="left_pinky_PIP_position" joint="left_pinky_PIP" />
    <position name="left_pinky_DIP_position" joint="left_pinky_DIP" />
  </actuator>
</mujoco>
